<?xml version="1.0" encoding="UTF-8"?>
<testng-results skipped="0" failed="1" total="2" passed="1">
  <reporter-output>
  </reporter-output>
  <suite name="Suite" duration-ms="64" started-at="2016-09-15T22:00:08Z" finished-at="2016-09-15T22:00:09Z">
    <groups>
    </groups>
    <test name="Test" duration-ms="64" started-at="2016-09-15T22:00:08Z" finished-at="2016-09-15T22:00:09Z">
      <class name="mymaventest.TestmavenDemo">
        <test-method status="FAIL" signature="test_to_fail()[pri:0, instance:mymaventest.TestmavenDemo@574516d4]" name="test_to_fail" duration-ms="26" started-at="2016-09-16T00:00:09Z" finished-at="2016-09-16T00:00:09Z">
          <exception class="java.lang.AssertionError">
            <message>
              <![CDATA[expected [2] but found [1]]]>
            </message>
            <full-stacktrace>
              <![CDATA[java.lang.AssertionError: expected [2] but found [1]
	at org.testng.Assert.fail(Assert.java:94)
	at org.testng.Assert.failNotEquals(Assert.java:494)
	at org.testng.Assert.assertEquals(Assert.java:123)
	at org.testng.Assert.assertEquals(Assert.java:370)
	at org.testng.Assert.assertEquals(Assert.java:380)
	at mymaventest.TestmavenDemo.test_to_fail(TestmavenDemo.java:19)
	at sun.reflect.NativeMethodAccessorImpl.invoke0(Native Method)
	at sun.reflect.NativeMethodAccessorImpl.invoke(NativeMethodAccessorImpl.java:57)
	at sun.reflect.DelegatingMethodAccessorImpl.invoke(DelegatingMethodAccessorImpl.java:43)
	at java.lang.reflect.Method.invoke(Method.java:606)
	at org.testng.internal.MethodInvocationHelper.invokeMethod(MethodInvocationHelper.java:80)
	at org.testng.internal.Invoker.invokeMethod(Invoker.java:714)
	at org.testng.internal.Invoker.invokeTestMethod(Invoker.java:901)
	at org.testng.internal.Invoker.invokeTestMethods(Invoker.java:1231)
	at org.testng.internal.TestMethodWorker.invokeTestMethods(TestMethodWorker.java:127)
	at org.testng.internal.TestMethodWorker.run(TestMethodWorker.java:111)
	at org.testng.TestRunner.privateRun(TestRunner.java:767)
	at org.testng.TestRunner.run(TestRunner.java:617)
	at org.testng.SuiteRunner.runTest(SuiteRunner.java:334)
	at org.testng.SuiteRunner.runSequentially(SuiteRunner.java:329)
	at org.testng.SuiteRunner.privateRun(SuiteRunner.java:291)
	at org.testng.SuiteRunner.run(SuiteRunner.java:240)
	at org.testng.SuiteRunnerWorker.runSuite(SuiteRunnerWorker.java:52)
	at org.testng.SuiteRunnerWorker.run(SuiteRunnerWorker.java:86)
	at org.testng.TestNG.runSuitesSequentially(TestNG.java:1198)
	at org.testng.TestNG.runSuitesLocally(TestNG.java:1123)
	at org.testng.TestNG.run(TestNG.java:1031)
	at org.testng.remote.AbstractRemoteTestNG.run(AbstractRemoteTestNG.java:126)
	at org.testng.remote.RemoteTestNG.initAndRun(RemoteTestNG.java:137)
	at org.testng.remote.RemoteTestNG.main(RemoteTestNG.java:58)
]]>
            </full-stacktrace>
          </exception> <!-- java.lang.AssertionError -->
          <reporter-output>
          </reporter-output>
        </test-method> <!-- test_to_fail -->
        <test-method status="PASS" signature="test_to_pass()[pri:0, instance:mymaventest.TestmavenDemo@574516d4]" name="test_to_pass" duration-ms="3" started-at="2016-09-16T00:00:09Z" finished-at="2016-09-16T00:00:09Z">
          <reporter-output>
          </reporter-output>
        </test-method> <!-- test_to_pass -->
      </class> <!-- mymaventest.TestmavenDemo -->
    </test> <!-- Test -->
  </suite> <!-- Suite -->
</testng-results>
